[2023-03-17 14:19:02,132] {taskinstance.py:1032} INFO - Dependencies all met for <TaskInstance: local_ingestion_v1.0.insert_logs_task manual__2023-03-17T14:18:13.652228+00:00 [queued]>
[2023-03-17 14:19:02,181] {taskinstance.py:1032} INFO - Dependencies all met for <TaskInstance: local_ingestion_v1.0.insert_logs_task manual__2023-03-17T14:18:13.652228+00:00 [queued]>
[2023-03-17 14:19:02,183] {taskinstance.py:1238} INFO - 
--------------------------------------------------------------------------------
[2023-03-17 14:19:02,184] {taskinstance.py:1239} INFO - Starting attempt 1 of 2
[2023-03-17 14:19:02,215] {taskinstance.py:1240} INFO - 
--------------------------------------------------------------------------------
[2023-03-17 14:19:02,267] {taskinstance.py:1259} INFO - Executing <Task(PostgresOperator): insert_logs_task> on 2023-03-17 14:18:13.652228+00:00
[2023-03-17 14:19:02,282] {standard_task_runner.py:52} INFO - Started process 2431 to run task
[2023-03-17 14:19:02,293] {standard_task_runner.py:76} INFO - Running: ['***', 'tasks', 'run', 'local_ingestion_v1.0', 'insert_logs_task', 'manual__2023-03-17T14:18:13.652228+00:00', '--job-id', '109', '--raw', '--subdir', 'DAGS_FOLDER/data_ingestion_local.py', '--cfg-path', '/tmp/tmp7av_cbhc', '--error-file', '/tmp/tmpt3rc50ru']
[2023-03-17 14:19:02,297] {standard_task_runner.py:77} INFO - Job 109: Subtask insert_logs_task
[2023-03-17 14:19:02,474] {logging_mixin.py:109} INFO - Running <TaskInstance: local_ingestion_v1.0.insert_logs_task manual__2023-03-17T14:18:13.652228+00:00 [running]> on host 8920ab98807f
[2023-03-17 14:19:02,645] {taskinstance.py:1700} ERROR - Task failed with exception
Traceback (most recent call last):
  File "/home/airflow/.local/lib/python3.7/site-packages/airflow/models/taskinstance.py", line 1329, in _run_raw_task
    self._execute_task_with_callbacks(context)
  File "/home/airflow/.local/lib/python3.7/site-packages/airflow/models/taskinstance.py", line 1418, in _execute_task_with_callbacks
    self.render_templates(context=context)
  File "/home/airflow/.local/lib/python3.7/site-packages/airflow/models/taskinstance.py", line 1992, in render_templates
    self.task.render_template_fields(context)
  File "/home/airflow/.local/lib/python3.7/site-packages/airflow/models/baseoperator.py", line 1061, in render_template_fields
    self._do_render_template_fields(self, self.template_fields, context, jinja_env, set())
  File "/home/airflow/.local/lib/python3.7/site-packages/airflow/models/baseoperator.py", line 1074, in _do_render_template_fields
    rendered_content = self.render_template(content, context, jinja_env, seen_oids)
  File "/home/airflow/.local/lib/python3.7/site-packages/airflow/models/baseoperator.py", line 1113, in render_template
    return render_template_to_string(template, context)
  File "/home/airflow/.local/lib/python3.7/site-packages/airflow/utils/helpers.py", line 268, in render_template_to_string
    return render_template(template, context, native=False)
  File "/home/airflow/.local/lib/python3.7/site-packages/airflow/utils/helpers.py", line 263, in render_template
    return "".join(nodes)
  File "<template>", line 16, in root
  File "/home/airflow/.local/lib/python3.7/site-packages/jinja2/runtime.py", line 903, in _fail_with_undefined_error
    raise self._undefined_exception(self._undefined_message)
jinja2.exceptions.UndefinedError: '***.models.dag.DAG object' has no attribute 'id'
[2023-03-17 14:19:02,838] {taskinstance.py:1277} INFO - Marking task as UP_FOR_RETRY. dag_id=local_ingestion_v1.0, task_id=insert_logs_task, execution_date=20230317T141813, start_date=20230317T141902, end_date=20230317T141902
[2023-03-17 14:19:03,061] {standard_task_runner.py:92} ERROR - Failed to execute job 109 for task insert_logs_task
Traceback (most recent call last):
  File "/home/airflow/.local/lib/python3.7/site-packages/airflow/task/task_runner/standard_task_runner.py", line 85, in _start_by_fork
    args.func(args, dag=self.dag)
  File "/home/airflow/.local/lib/python3.7/site-packages/airflow/cli/cli_parser.py", line 48, in command
    return func(*args, **kwargs)
  File "/home/airflow/.local/lib/python3.7/site-packages/airflow/utils/cli.py", line 92, in wrapper
    return f(*args, **kwargs)
  File "/home/airflow/.local/lib/python3.7/site-packages/airflow/cli/commands/task_command.py", line 298, in task_run
    _run_task_by_selected_method(args, dag, ti)
  File "/home/airflow/.local/lib/python3.7/site-packages/airflow/cli/commands/task_command.py", line 107, in _run_task_by_selected_method
    _run_raw_task(args, ti)
  File "/home/airflow/.local/lib/python3.7/site-packages/airflow/cli/commands/task_command.py", line 184, in _run_raw_task
    error_file=args.error_file,
  File "/home/airflow/.local/lib/python3.7/site-packages/airflow/utils/session.py", line 70, in wrapper
    return func(*args, session=session, **kwargs)
  File "/home/airflow/.local/lib/python3.7/site-packages/airflow/models/taskinstance.py", line 1329, in _run_raw_task
    self._execute_task_with_callbacks(context)
  File "/home/airflow/.local/lib/python3.7/site-packages/airflow/models/taskinstance.py", line 1418, in _execute_task_with_callbacks
    self.render_templates(context=context)
  File "/home/airflow/.local/lib/python3.7/site-packages/airflow/models/taskinstance.py", line 1992, in render_templates
    self.task.render_template_fields(context)
  File "/home/airflow/.local/lib/python3.7/site-packages/airflow/models/baseoperator.py", line 1061, in render_template_fields
    self._do_render_template_fields(self, self.template_fields, context, jinja_env, set())
  File "/home/airflow/.local/lib/python3.7/site-packages/airflow/models/baseoperator.py", line 1074, in _do_render_template_fields
    rendered_content = self.render_template(content, context, jinja_env, seen_oids)
  File "/home/airflow/.local/lib/python3.7/site-packages/airflow/models/baseoperator.py", line 1113, in render_template
    return render_template_to_string(template, context)
  File "/home/airflow/.local/lib/python3.7/site-packages/airflow/utils/helpers.py", line 268, in render_template_to_string
    return render_template(template, context, native=False)
  File "/home/airflow/.local/lib/python3.7/site-packages/airflow/utils/helpers.py", line 263, in render_template
    return "".join(nodes)
  File "<template>", line 16, in root
  File "/home/airflow/.local/lib/python3.7/site-packages/jinja2/runtime.py", line 903, in _fail_with_undefined_error
    raise self._undefined_exception(self._undefined_message)
jinja2.exceptions.UndefinedError: '***.models.dag.DAG object' has no attribute 'id'
[2023-03-17 14:19:03,114] {local_task_job.py:154} INFO - Task exited with return code 1
[2023-03-17 14:19:03,296] {local_task_job.py:264} INFO - 0 downstream tasks scheduled from follow-on schedule check
