[2023-03-17 14:11:08,197] {taskinstance.py:1032} INFO - Dependencies all met for <TaskInstance: local_ingestion_v1.0.create_log_task_table manual__2023-03-17T14:10:46.193794+00:00 [queued]>
[2023-03-17 14:11:08,246] {taskinstance.py:1032} INFO - Dependencies all met for <TaskInstance: local_ingestion_v1.0.create_log_task_table manual__2023-03-17T14:10:46.193794+00:00 [queued]>
[2023-03-17 14:11:08,249] {taskinstance.py:1238} INFO - 
--------------------------------------------------------------------------------
[2023-03-17 14:11:08,253] {taskinstance.py:1239} INFO - Starting attempt 1 of 2
[2023-03-17 14:11:08,255] {taskinstance.py:1240} INFO - 
--------------------------------------------------------------------------------
[2023-03-17 14:11:08,331] {taskinstance.py:1259} INFO - Executing <Task(PostgresOperator): create_log_task_table> on 2023-03-17 14:10:46.193794+00:00
[2023-03-17 14:11:08,345] {standard_task_runner.py:52} INFO - Started process 1790 to run task
[2023-03-17 14:11:08,355] {standard_task_runner.py:76} INFO - Running: ['***', 'tasks', 'run', 'local_ingestion_v1.0', 'create_log_task_table', 'manual__2023-03-17T14:10:46.193794+00:00', '--job-id', '97', '--raw', '--subdir', 'DAGS_FOLDER/data_ingestion_local.py', '--cfg-path', '/tmp/tmpfctma7ly', '--error-file', '/tmp/tmpx0tg4o92']
[2023-03-17 14:11:08,360] {standard_task_runner.py:77} INFO - Job 97: Subtask create_log_task_table
[2023-03-17 14:11:08,586] {logging_mixin.py:109} INFO - Running <TaskInstance: local_ingestion_v1.0.create_log_task_table manual__2023-03-17T14:10:46.193794+00:00 [running]> on host 8920ab98807f
[2023-03-17 14:11:08,786] {taskinstance.py:1426} INFO - Exporting the following env vars:
AIRFLOW_CTX_DAG_OWNER=***
AIRFLOW_CTX_DAG_ID=local_ingestion_v1.0
AIRFLOW_CTX_TASK_ID=create_log_task_table
AIRFLOW_CTX_EXECUTION_DATE=2023-03-17T14:10:46.193794+00:00
AIRFLOW_CTX_DAG_RUN_ID=manual__2023-03-17T14:10:46.193794+00:00
[2023-03-17 14:11:08,822] {base.py:79} INFO - Using connection to: id: postgress_localhost. Host: host.docker.internal, Port: 5432, Schema: wine_quality, Login: ***, Password: ***, extra: {}
[2023-03-17 14:11:08,897] {dbapi.py:225} INFO - Running statement: 
            create table if not exists dag_runs (
                dt date,
                dag_id character varying,
                primary key (dt, dat_id)
            )
        , parameters: None
[2023-03-17 14:11:08,915] {taskinstance.py:1700} ERROR - Task failed with exception
Traceback (most recent call last):
  File "/home/airflow/.local/lib/python3.7/site-packages/airflow/models/taskinstance.py", line 1329, in _run_raw_task
    self._execute_task_with_callbacks(context)
  File "/home/airflow/.local/lib/python3.7/site-packages/airflow/models/taskinstance.py", line 1455, in _execute_task_with_callbacks
    result = self._execute_task(context, self.task)
  File "/home/airflow/.local/lib/python3.7/site-packages/airflow/models/taskinstance.py", line 1511, in _execute_task
    result = execute_callable(context=context)
  File "/home/airflow/.local/lib/python3.7/site-packages/airflow/providers/postgres/operators/postgres.py", line 69, in execute
    self.hook.run(self.sql, self.autocommit, parameters=self.parameters)
  File "/home/airflow/.local/lib/python3.7/site-packages/airflow/hooks/dbapi.py", line 205, in run
    self._run_command(cur, sql_statement, parameters)
  File "/home/airflow/.local/lib/python3.7/site-packages/airflow/hooks/dbapi.py", line 229, in _run_command
    cur.execute(sql_statement)
psycopg2.errors.UndefinedColumn: column "dat_id" named in key does not exist
LINE 5:                 primary key (dt, dat_id)
                        ^

[2023-03-17 14:11:09,000] {taskinstance.py:1277} INFO - Marking task as UP_FOR_RETRY. dag_id=local_ingestion_v1.0, task_id=create_log_task_table, execution_date=20230317T141046, start_date=20230317T141108, end_date=20230317T141108
[2023-03-17 14:11:09,100] {standard_task_runner.py:92} ERROR - Failed to execute job 97 for task create_log_task_table
Traceback (most recent call last):
  File "/home/airflow/.local/lib/python3.7/site-packages/airflow/task/task_runner/standard_task_runner.py", line 85, in _start_by_fork
    args.func(args, dag=self.dag)
  File "/home/airflow/.local/lib/python3.7/site-packages/airflow/cli/cli_parser.py", line 48, in command
    return func(*args, **kwargs)
  File "/home/airflow/.local/lib/python3.7/site-packages/airflow/utils/cli.py", line 92, in wrapper
    return f(*args, **kwargs)
  File "/home/airflow/.local/lib/python3.7/site-packages/airflow/cli/commands/task_command.py", line 298, in task_run
    _run_task_by_selected_method(args, dag, ti)
  File "/home/airflow/.local/lib/python3.7/site-packages/airflow/cli/commands/task_command.py", line 107, in _run_task_by_selected_method
    _run_raw_task(args, ti)
  File "/home/airflow/.local/lib/python3.7/site-packages/airflow/cli/commands/task_command.py", line 184, in _run_raw_task
    error_file=args.error_file,
  File "/home/airflow/.local/lib/python3.7/site-packages/airflow/utils/session.py", line 70, in wrapper
    return func(*args, session=session, **kwargs)
  File "/home/airflow/.local/lib/python3.7/site-packages/airflow/models/taskinstance.py", line 1329, in _run_raw_task
    self._execute_task_with_callbacks(context)
  File "/home/airflow/.local/lib/python3.7/site-packages/airflow/models/taskinstance.py", line 1455, in _execute_task_with_callbacks
    result = self._execute_task(context, self.task)
  File "/home/airflow/.local/lib/python3.7/site-packages/airflow/models/taskinstance.py", line 1511, in _execute_task
    result = execute_callable(context=context)
  File "/home/airflow/.local/lib/python3.7/site-packages/airflow/providers/postgres/operators/postgres.py", line 69, in execute
    self.hook.run(self.sql, self.autocommit, parameters=self.parameters)
  File "/home/airflow/.local/lib/python3.7/site-packages/airflow/hooks/dbapi.py", line 205, in run
    self._run_command(cur, sql_statement, parameters)
  File "/home/airflow/.local/lib/python3.7/site-packages/airflow/hooks/dbapi.py", line 229, in _run_command
    cur.execute(sql_statement)
psycopg2.errors.UndefinedColumn: column "dat_id" named in key does not exist
LINE 5:                 primary key (dt, dat_id)
                        ^

[2023-03-17 14:11:09,187] {local_task_job.py:154} INFO - Task exited with return code 1
[2023-03-17 14:11:09,407] {local_task_job.py:264} INFO - 0 downstream tasks scheduled from follow-on schedule check
