[2023-03-17 14:21:38,068] {taskinstance.py:1032} INFO - Dependencies all met for <TaskInstance: local_ingestion_v1.0.insert_logs_task manual__2023-03-17T14:21:12.564230+00:00 [queued]>
[2023-03-17 14:21:38,118] {taskinstance.py:1032} INFO - Dependencies all met for <TaskInstance: local_ingestion_v1.0.insert_logs_task manual__2023-03-17T14:21:12.564230+00:00 [queued]>
[2023-03-17 14:21:38,121] {taskinstance.py:1238} INFO - 
--------------------------------------------------------------------------------
[2023-03-17 14:21:38,123] {taskinstance.py:1239} INFO - Starting attempt 1 of 2
[2023-03-17 14:21:38,141] {taskinstance.py:1240} INFO - 
--------------------------------------------------------------------------------
[2023-03-17 14:21:38,187] {taskinstance.py:1259} INFO - Executing <Task(PostgresOperator): insert_logs_task> on 2023-03-17 14:21:12.564230+00:00
[2023-03-17 14:21:38,201] {standard_task_runner.py:52} INFO - Started process 2638 to run task
[2023-03-17 14:21:38,211] {standard_task_runner.py:76} INFO - Running: ['***', 'tasks', 'run', 'local_ingestion_v1.0', 'insert_logs_task', 'manual__2023-03-17T14:21:12.564230+00:00', '--job-id', '114', '--raw', '--subdir', 'DAGS_FOLDER/data_ingestion_local.py', '--cfg-path', '/tmp/tmp7eqsycj4', '--error-file', '/tmp/tmp11zg7_wm']
[2023-03-17 14:21:38,215] {standard_task_runner.py:77} INFO - Job 114: Subtask insert_logs_task
[2023-03-17 14:21:38,418] {logging_mixin.py:109} INFO - Running <TaskInstance: local_ingestion_v1.0.insert_logs_task manual__2023-03-17T14:21:12.564230+00:00 [running]> on host 8920ab98807f
[2023-03-17 14:21:38,704] {taskinstance.py:1426} INFO - Exporting the following env vars:
AIRFLOW_CTX_DAG_OWNER=***
AIRFLOW_CTX_DAG_ID=local_ingestion_v1.0
AIRFLOW_CTX_TASK_ID=insert_logs_task
AIRFLOW_CTX_EXECUTION_DATE=2023-03-17T14:21:12.564230+00:00
AIRFLOW_CTX_DAG_RUN_ID=manual__2023-03-17T14:21:12.564230+00:00
[2023-03-17 14:21:38,732] {base.py:79} INFO - Using connection to: id: postgress_localhost. Host: host.docker.internal, Port: 5432, Schema: wine_quality, Login: ***, Password: ***, extra: {}
[2023-03-17 14:21:38,775] {dbapi.py:225} INFO - Running statement: 
            insert into dag_runs (dt, dag_id) values ('2023-03-17', 'local_ingestion_v1.0')
        , parameters: None
[2023-03-17 14:21:38,797] {taskinstance.py:1700} ERROR - Task failed with exception
Traceback (most recent call last):
  File "/home/airflow/.local/lib/python3.7/site-packages/airflow/models/taskinstance.py", line 1329, in _run_raw_task
    self._execute_task_with_callbacks(context)
  File "/home/airflow/.local/lib/python3.7/site-packages/airflow/models/taskinstance.py", line 1455, in _execute_task_with_callbacks
    result = self._execute_task(context, self.task)
  File "/home/airflow/.local/lib/python3.7/site-packages/airflow/models/taskinstance.py", line 1511, in _execute_task
    result = execute_callable(context=context)
  File "/home/airflow/.local/lib/python3.7/site-packages/airflow/providers/postgres/operators/postgres.py", line 69, in execute
    self.hook.run(self.sql, self.autocommit, parameters=self.parameters)
  File "/home/airflow/.local/lib/python3.7/site-packages/airflow/hooks/dbapi.py", line 205, in run
    self._run_command(cur, sql_statement, parameters)
  File "/home/airflow/.local/lib/python3.7/site-packages/airflow/hooks/dbapi.py", line 229, in _run_command
    cur.execute(sql_statement)
psycopg2.errors.UniqueViolation: duplicate key value violates unique constraint "dag_runs_pkey"
DETAIL:  Key (dt, dag_id)=(2023-03-17, local_ingestion_v1.0) already exists.

[2023-03-17 14:21:38,856] {taskinstance.py:1277} INFO - Marking task as UP_FOR_RETRY. dag_id=local_ingestion_v1.0, task_id=insert_logs_task, execution_date=20230317T142112, start_date=20230317T142138, end_date=20230317T142138
[2023-03-17 14:21:38,943] {standard_task_runner.py:92} ERROR - Failed to execute job 114 for task insert_logs_task
Traceback (most recent call last):
  File "/home/airflow/.local/lib/python3.7/site-packages/airflow/task/task_runner/standard_task_runner.py", line 85, in _start_by_fork
    args.func(args, dag=self.dag)
  File "/home/airflow/.local/lib/python3.7/site-packages/airflow/cli/cli_parser.py", line 48, in command
    return func(*args, **kwargs)
  File "/home/airflow/.local/lib/python3.7/site-packages/airflow/utils/cli.py", line 92, in wrapper
    return f(*args, **kwargs)
  File "/home/airflow/.local/lib/python3.7/site-packages/airflow/cli/commands/task_command.py", line 298, in task_run
    _run_task_by_selected_method(args, dag, ti)
  File "/home/airflow/.local/lib/python3.7/site-packages/airflow/cli/commands/task_command.py", line 107, in _run_task_by_selected_method
    _run_raw_task(args, ti)
  File "/home/airflow/.local/lib/python3.7/site-packages/airflow/cli/commands/task_command.py", line 184, in _run_raw_task
    error_file=args.error_file,
  File "/home/airflow/.local/lib/python3.7/site-packages/airflow/utils/session.py", line 70, in wrapper
    return func(*args, session=session, **kwargs)
  File "/home/airflow/.local/lib/python3.7/site-packages/airflow/models/taskinstance.py", line 1329, in _run_raw_task
    self._execute_task_with_callbacks(context)
  File "/home/airflow/.local/lib/python3.7/site-packages/airflow/models/taskinstance.py", line 1455, in _execute_task_with_callbacks
    result = self._execute_task(context, self.task)
  File "/home/airflow/.local/lib/python3.7/site-packages/airflow/models/taskinstance.py", line 1511, in _execute_task
    result = execute_callable(context=context)
  File "/home/airflow/.local/lib/python3.7/site-packages/airflow/providers/postgres/operators/postgres.py", line 69, in execute
    self.hook.run(self.sql, self.autocommit, parameters=self.parameters)
  File "/home/airflow/.local/lib/python3.7/site-packages/airflow/hooks/dbapi.py", line 205, in run
    self._run_command(cur, sql_statement, parameters)
  File "/home/airflow/.local/lib/python3.7/site-packages/airflow/hooks/dbapi.py", line 229, in _run_command
    cur.execute(sql_statement)
psycopg2.errors.UniqueViolation: duplicate key value violates unique constraint "dag_runs_pkey"
DETAIL:  Key (dt, dag_id)=(2023-03-17, local_ingestion_v1.0) already exists.

[2023-03-17 14:21:39,035] {local_task_job.py:154} INFO - Task exited with return code 1
[2023-03-17 14:21:39,582] {local_task_job.py:264} INFO - 0 downstream tasks scheduled from follow-on schedule check
