[2023-03-16 16:32:19,449] {taskinstance.py:1032} INFO - Dependencies all met for <TaskInstance: local_ingestion_v1.0.ingest_data manual__2023-03-16T16:32:06.152951+00:00 [queued]>
[2023-03-16 16:32:19,498] {taskinstance.py:1032} INFO - Dependencies all met for <TaskInstance: local_ingestion_v1.0.ingest_data manual__2023-03-16T16:32:06.152951+00:00 [queued]>
[2023-03-16 16:32:19,501] {taskinstance.py:1238} INFO - 
--------------------------------------------------------------------------------
[2023-03-16 16:32:19,503] {taskinstance.py:1239} INFO - Starting attempt 1 of 2
[2023-03-16 16:32:19,504] {taskinstance.py:1240} INFO - 
--------------------------------------------------------------------------------
[2023-03-16 16:32:19,553] {taskinstance.py:1259} INFO - Executing <Task(PythonOperator): ingest_data> on 2023-03-16 16:32:06.152951+00:00
[2023-03-16 16:32:19,570] {standard_task_runner.py:52} INFO - Started process 4203 to run task
[2023-03-16 16:32:19,581] {standard_task_runner.py:76} INFO - Running: ['***', 'tasks', 'run', 'local_ingestion_v1.0', 'ingest_data', 'manual__2023-03-16T16:32:06.152951+00:00', '--job-id', '61', '--raw', '--subdir', 'DAGS_FOLDER/data_ingestion_local.py', '--cfg-path', '/tmp/tmp9bs8ddsl', '--error-file', '/tmp/tmpzfvfuth_']
[2023-03-16 16:32:19,636] {standard_task_runner.py:77} INFO - Job 61: Subtask ingest_data
[2023-03-16 16:32:19,885] {logging_mixin.py:109} INFO - Running <TaskInstance: local_ingestion_v1.0.ingest_data manual__2023-03-16T16:32:06.152951+00:00 [running]> on host c6eb90394236
[2023-03-16 16:32:20,370] {taskinstance.py:1426} INFO - Exporting the following env vars:
AIRFLOW_CTX_DAG_OWNER=***
AIRFLOW_CTX_DAG_ID=local_ingestion_v1.0
AIRFLOW_CTX_TASK_ID=ingest_data
AIRFLOW_CTX_EXECUTION_DATE=2023-03-16T16:32:06.152951+00:00
AIRFLOW_CTX_DAG_RUN_ID=manual__2023-03-16T16:32:06.152951+00:00
[2023-03-16 16:32:20,401] {taskinstance.py:1700} ERROR - Task failed with exception
Traceback (most recent call last):
  File "/home/airflow/.local/lib/python3.7/site-packages/airflow/models/taskinstance.py", line 1329, in _run_raw_task
    self._execute_task_with_callbacks(context)
  File "/home/airflow/.local/lib/python3.7/site-packages/airflow/models/taskinstance.py", line 1455, in _execute_task_with_callbacks
    result = self._execute_task(context, self.task)
  File "/home/airflow/.local/lib/python3.7/site-packages/airflow/models/taskinstance.py", line 1511, in _execute_task
    result = execute_callable(context=context)
  File "/home/airflow/.local/lib/python3.7/site-packages/airflow/operators/python.py", line 174, in execute
    return_value = self.execute_callable()
  File "/home/airflow/.local/lib/python3.7/site-packages/airflow/operators/python.py", line 185, in execute_callable
    return self.python_callable(*self.op_args, **self.op_kwargs)
  File "/opt/airflow/dags/ingest_data.py", line 15, in ingest_callable
    print(df_iter.head(10))
AttributeError: 'TextFileReader' object has no attribute 'head'
[2023-03-16 16:32:20,468] {taskinstance.py:1277} INFO - Marking task as UP_FOR_RETRY. dag_id=local_ingestion_v1.0, task_id=ingest_data, execution_date=20230316T163206, start_date=20230316T163219, end_date=20230316T163220
[2023-03-16 16:32:20,518] {standard_task_runner.py:92} ERROR - Failed to execute job 61 for task ingest_data
Traceback (most recent call last):
  File "/home/airflow/.local/lib/python3.7/site-packages/airflow/task/task_runner/standard_task_runner.py", line 85, in _start_by_fork
    args.func(args, dag=self.dag)
  File "/home/airflow/.local/lib/python3.7/site-packages/airflow/cli/cli_parser.py", line 48, in command
    return func(*args, **kwargs)
  File "/home/airflow/.local/lib/python3.7/site-packages/airflow/utils/cli.py", line 92, in wrapper
    return f(*args, **kwargs)
  File "/home/airflow/.local/lib/python3.7/site-packages/airflow/cli/commands/task_command.py", line 298, in task_run
    _run_task_by_selected_method(args, dag, ti)
  File "/home/airflow/.local/lib/python3.7/site-packages/airflow/cli/commands/task_command.py", line 107, in _run_task_by_selected_method
    _run_raw_task(args, ti)
  File "/home/airflow/.local/lib/python3.7/site-packages/airflow/cli/commands/task_command.py", line 184, in _run_raw_task
    error_file=args.error_file,
  File "/home/airflow/.local/lib/python3.7/site-packages/airflow/utils/session.py", line 70, in wrapper
    return func(*args, session=session, **kwargs)
  File "/home/airflow/.local/lib/python3.7/site-packages/airflow/models/taskinstance.py", line 1329, in _run_raw_task
    self._execute_task_with_callbacks(context)
  File "/home/airflow/.local/lib/python3.7/site-packages/airflow/models/taskinstance.py", line 1455, in _execute_task_with_callbacks
    result = self._execute_task(context, self.task)
  File "/home/airflow/.local/lib/python3.7/site-packages/airflow/models/taskinstance.py", line 1511, in _execute_task
    result = execute_callable(context=context)
  File "/home/airflow/.local/lib/python3.7/site-packages/airflow/operators/python.py", line 174, in execute
    return_value = self.execute_callable()
  File "/home/airflow/.local/lib/python3.7/site-packages/airflow/operators/python.py", line 185, in execute_callable
    return self.python_callable(*self.op_args, **self.op_kwargs)
  File "/opt/airflow/dags/ingest_data.py", line 15, in ingest_callable
    print(df_iter.head(10))
AttributeError: 'TextFileReader' object has no attribute 'head'
[2023-03-16 16:32:20,544] {local_task_job.py:154} INFO - Task exited with return code 1
[2023-03-16 16:32:20,645] {local_task_job.py:264} INFO - 0 downstream tasks scheduled from follow-on schedule check
